<?xml version="1.0"?>
<robot name="tamiyanbot">

  <!-- base_footprint -->
  <link name="base_footprint"/>

  <!-- base_joint -->
  <joint name="base_joint" type="fixed">
    <parent link="base_footprint"/>
    <child link="base_link"/>
    <origin xyz="0 0 0.04" rpy="0 0 0"/>
  </joint>

  <!-- base_link -->
  <link name="base_link">
    <visual>
      <origin xyz="0 0 0" rpy="0 0 0"/>
      <geometry>
        <box size="0.16 0.14 0.070"/>
      </geometry>
      <material name="light_black">
        <color rgba=".5 .5 .5 1"/>
      </material>
    </visual>

    <collision>
      <origin xyz="0 0 0" rpy="0 0 0"/>
      <geometry>
        <box size="0.16 0.14 0.070"/>
      </geometry>
    </collision>

    <!-- inertial>
      <origin xyz="0 0 0" rpy="0 0 0"/>
      <mass value="0.12"/>
      <inertia ixx="0.0003050" ixy="0.0" ixz="0.0" iyy="0.0002450" iyz="0.0" izz="0.000452" />
    </inertial -->
    <inertial>
      <origin xyz="0 0 0" rpy="0 0 0"/>
      <mass value="0.03"/>
      <inertia ixx="0.00009325" ixy="0.0" ixz="0.0" iyy="0.00007625" iyz="0.0" izz="0.000145" />
    </inertial>

  </link>

  <!-- wheel_left_joint -->
  <joint name="wheel_left_joint" type="continuous">
    <parent link="base_link"/>
    <child link="wheel_left_link"/>
    <origin xyz="0.05 0.09 -0.035" rpy="-1.57 0 0"/>
    <axis xyz="0 0 1"/>
  </joint>

  <!-- wheel_left_link -->
  <link name="wheel_left_link">
    <visual>
      <origin xyz="0 0 0" rpy="0 0 0"/>
      <geometry>
        <cylinder radius="0.018" length="0.004"/>
      </geometry>
      <material name="white">
        <color rgba="1 1 1 1"/>
      </material>
    </visual>

    <collision>
      <origin xyz="0 0 0" rpy="0 0 0"/>
      <geometry>
         <cylinder radius="0.018" length="0.004"/>
      </geometry>
    </collision>

    <inertial>
      <origin xyz="0 0 0"/>
      <mass value="0.01"/>
      <inertia ixx="0.0000008" ixy="0" ixz="0" iyy="0.0000008" iyz="0" izz="0.0000016"/>
    </inertial>
  </link>

  <!-- wheel_right_joint -->
  <joint name="wheel_right_joint" type="continuous">
    <parent link="base_link"/>
    <child link="wheel_right_link"/>
    <origin xyz="0.05 -0.09 -0.035" rpy="-1.57 0 0"/>
    <axis xyz="0 0 1"/>
  </joint>

  <!-- wheel_right_link -->
  <link name="wheel_right_link">
    <visual>
      <origin xyz="0 0 0" rpy="0 0 0"/>
      <geometry>
        <cylinder radius="0.018" length="0.004"/>
      </geometry>
      <material name="white">
        <color rgba="1 1 1 1"/>
      </material>
    </visual>

    <collision>
      <origin xyz="0 0 0" rpy="0 0 0"/>
      <geometry>
        <cylinder radius="0.018" length="0.004"/>
      </geometry>
    </collision>

    <inertial>
      <origin xyz="0 0 0" />
      <mass value="0.008"/>
      <inertia ixx="0.0000008" ixy="0" ixz="0" iyy="0.0000008" iyz="0" izz="0.0000016"/>
    </inertial>
  </link>

  <!-- caster_left_joint -->
  <joint name="caster_left_joint" type="fixed">
    <parent link="base_link"/>
    <child link="caster_left_link"/>
    <origin xyz="-0.06 -0.05 -0.035" rpy="0 0 0"/>
  </joint>

  <!-- caster_left_link -->
  <link name="caster_left_link">
    <visual>
      <geometry>
        <sphere radius="0.018"/>
      </geometry>
      <material name="dark black">
        <color rgba=".5 .5 .5 1"/>
      </material>
    </visual>

    <collision>
      <origin xyz="0 0 0" rpy="0 0 0"/>
      <geometry>
        <sphere radius="0.018"/>
      </geometry>
    </collision>

    <inertial>
      <origin xyz="0 0 0" />
      <mass value="0.02" />
      <inertia ixx="0.0000026" ixy="0.0" ixz="0.0" iyy="0.0000026" iyz="0.0" izz="0.0000026" />
    </inertial>
  </link>

  <!-- caster_right_joint -->
  <joint name="caster_right_joint" type="fixed">
    <parent link="base_link"/>
    <child link="caster_right_link"/>
    <origin xyz="-0.06 0.05 -0.035" rpy="0 0 0"/>
  </joint>

  <!-- caster_right_link -->
  <link name="caster_right_link">
    <visual>
      <geometry>
        <sphere radius="0.018"/>
      </geometry>
      <material name="dark black">
        <color rgba=".5 .5 .5 1"/>
      </material>
    </visual>

    <collision>
      <origin xyz="0 0 0" rpy="0 0 0"/>
      <geometry>
        <sphere radius="0.018"/>
      </geometry>
    </collision>

    <inertial>
      <origin xyz="0 0 0" />
      <mass value="0.02" />
      <inertia ixx="0.0000026" ixy="0.0" ixz="0.0" iyy="0.0000026" iyz="0.0" izz="0.0000026" />
    </inertial>
  </link>

  <!-- imu_joint -->
  <joint name="imu_joint" type="fixed">
    <parent link="base_link"/>
    <child link="imu_link"/>
    <origin xyz="-0.032 0 0.068" rpy="0 0 0"/>
  </joint>

  <!-- imu_link -->
  <link name="imu_link"/>

  <!-- scan_joint -->
  <joint name="scan_joint" type="fixed">
    <parent link="base_link"/>
    <child link="scan_link"/>
    <origin xyz="0 0 0.07" rpy="0 0 0"/>
  </joint>

  <!-- scan_link -->
  <link name="scan_link">
    <visual>
      <origin xyz="0 0 0" rpy="0 0 0"/>
      <geometry>
         <cylinder radius="0.03" length="0.07"/>
      </geometry>
      <material name="blue">
        <color rgba="0 0 1 1"/>
      </material>
    </visual>

    <collision>
      <origin xyz="0 0 0" rpy="0 0 0"/>
      <geometry>
         <cylinder radius="0.03" length="0.07"/>
      </geometry>
    </collision>

    <inertial>
      <mass value="0.1" />
      <origin xyz="0 0 0" />
      <inertia ixx="0.000063" ixy="0" ixz="0" iyy="0.000063" iyz="0" izz="0.000045" />
    </inertial>
  </link>

  <!-- camera joint -->
  <joint name="camera_joint" type="fixed">
      <origin xyz="0.10 -0.03 0.005" rpy="0 0 0"/>
      <parent link="base_link"/>
      <child link="camera_link"/>
      <axis xyz="0.0 0.0 1.0"/>
  </joint>

  <!-- camera link -->
  <link name="camera_link">
      <inertial>
          <mass value="0.00"/>
          <inertia ixx="0.0" ixy="0.0" ixz="0" iyy="0.0" iyz="0" izz="0.0"/>
      </inertial>
      <visual>
        <geometry>
            <box size="0.02 0.04 0.03"/>
        </geometry>
        <material name="dark">
          <color rgba=".3 .3 .3 1"/>
        </material>
      </visual>
  </link>

  <gazebo>
    <plugin name="diff_drive" filename="libgazebo_ros_diff_drive.so">
      <ros>
        <!-- namespace>/tb3</namespace -->
      </ros>

      <update_rate>30</update_rate>

      <!-- wheels -->
      <left_joint>wheel_left_joint</left_joint>
      <right_joint>wheel_right_joint</right_joint>

      <!-- kinematics -->
      <wheel_separation>0.09</wheel_separation>
      <wheel_diameter>0.036</wheel_diameter>

      <!-- limits -->
      <max_wheel_torque>1.427</max_wheel_torque> <!-- Nm -->
      <!--  Nm (1 m/s^2 for 1kg) -->
      <!-- accel = Torque(Nm) / (mass(kg) x radius(m))-->
      <!-- rad_accel (rad/s^2) = Torque(Nm) / Moment of Inertia -->
      <!-- moment of inertia = mass x radius -->
      <max_wheel_acceleration>0.2</max_wheel_acceleration>
      <command_topic>cmd_vel</command_topic>

      <!-- output -->
      <publish_odom>true</publish_odom>
      <!-- "publish_odom_tf" should be "false" when running the cartography -->
      <publish_odom_tf>false</publish_odom_tf>
      <publish_wheel_tf>false</publish_wheel_tf>

      <odometry_topic>odom</odometry_topic>
      <odometry_frame>odom</odometry_frame>
      
      <!-- base_frame_id>base_footprint</base_frame_id -->
      <robot_base_frame>base_footprint</robot_base_frame>

    </plugin>
  </gazebo>

  <gazebo reference="imu_link">
    <sensor name="imu" type="imu">
      <plugin name="imu" filename="libgazebo_ros_imu_sensor.so">
        <ros>
          <!-- <namespace>/tb</namespace> -->
          <remapping>~/out:=imu</remapping>
        </ros>
      </plugin>
      <always_on>true</always_on>
      <update_rate>30</update_rate>

      <imu>
        <angular_velocity>
          <x>
            <noise type="gaussian">
              <mean>0.0</mean>
              <stddev>2e-4</stddev>
            </noise>
          </x>
          <y>
            <noise type="gaussian">
              <mean>0.0</mean>
              <stddev>2e-4</stddev>
            </noise>
          </y>
          <z>
            <noise type="gaussian">
              <mean>0.0</mean>
              <stddev>2e-4</stddev>
            </noise>
          </z>
        </angular_velocity>

        <linear_acceleration>
          <x>
            <noise type="gaussian">
              <mean>0.0</mean>
              <stddev>1.7e-2</stddev>
            </noise>
          </x>
          <y>
            <noise type="gaussian">
              <mean>0.0</mean>
              <stddev>1.7e-2</stddev>
            </noise>
          </y>
          <z>
            <noise type="gaussian">
              <mean>0.0</mean>
              <stddev>1.7e-2</stddev>
            </noise>
          </z>
        </linear_acceleration>
      </imu>
    </sensor>
  </gazebo>

  <gazebo reference="scan_link">
    <sensor name="LiDAR" type="ray">
      <plugin name="laserscan" filename="libgazebo_ros_ray_sensor.so">
        <ros>
          <remapping>~/out:=scan</remapping>
        </ros>
        <output_type>sensor_msgs/LaserScan</output_type>
        <frame_name>scan_link</frame_name>
      </plugin>
      <always_on>true</always_on>
      <visualize>true</visualize>
      <pose>-0.032 0 0.171 0 0 0</pose>
      <update_rate>5</update_rate>
      <ray>
        <scan>
          <horizontal>
            <samples>360</samples>
            <resolution>1.000000</resolution>
            <min_angle>0.000000</min_angle>
            <max_angle>6.280000</max_angle>
          </horizontal>
        </scan>
        <range>
          <min>0.120000</min>
          <max>3.5</max>
          <resolution>0.015000</resolution>
        </range>
        <noise>
          <type>gaussian</type>
          <mean>0.0</mean>
          <stddev>0.01</stddev>
        </noise>
      </ray>
    </sensor>
  </gazebo>

  <!-- camera plugin -->
  <gazebo reference="camera_link">
    <sensor type="camera" name="camera1">
      <plugin name="camera_controller" filename=  "libgazebo_ros_camera.so">
          <cameraName>/camera</cameraName>
          <imageTopicName>image_raw</imageTopicName>
          <cameraInfoTopicName>camera_info</cameraInfoTopicName>
          <frameName>camera_link</frameName>
          <hackBaseline>0.07</hackBaseline>
      </plugin>
      <alwaysOn>true</alwaysOn>
      <visualize>true</visualize>
      <update_rate>10.0</update_rate>
      <camera name="head">
          <horizontal_fov>1.3962634</horizontal_fov>
          <image>
              <width>800</width>
              <height>800</height>
              <format>R8G8B8</format>
          </image>
          <clip>
              <near>0.02</near>
              <far>300</far>
          </clip>
          <noise>
              <type>gaussian</type>
              <mean>0.0</mean>
              <stddev>0.007</stddev>
          </noise>
      </camera>
    </sensor>
  </gazebo>

</robot>
